<?xml version="1.0" ?>
<sdf version="1.4">
<model name="exo">
  
  	<static>False</static>

  	<!-- dizuo -->
  		<link name="base">
  			<inertial>
  				<mass>1000</mass>
  			</inertial>
			<collision name='col_plate_on_ground'>
				<pose>0 0 0.01 0 0 0</pose>
				<geometry>
					<cylinder>
						<radius>0.5</radius>
						<length>0.02</length>
					</cylinder>
				</geometry>
			</collision>

			<collision name='col_vertical_pole'>
				<pose>0 0 0.8 0 0 0</pose>
				<geometry>
					<cylinder>
						<radius>0.05</radius>
						<length>1.6</length>
					</cylinder>
				</geometry>
			</collision>

			<collision name='col_horizontal_pole'>
				<pose>0 0 1.6 1.5708 0 0</pose>
				<geometry>
					<cylinder>
						<radius>0.025</radius>
						<length>1</length>
					</cylinder>
				</geometry>
			</collision>

			<visual name='vis_plat_on_ground'>
				<pose>0 0 0.01 0 0 0</pose>
				<geometry>
					<cylinder>
						<radius>0.5</radius>
						<length>0.02</length>
					</cylinder>
				</geometry>
			</visual>

			<visual name='vis_vertical_pole'>
				<pose>0 0 0.8 0 0 0</pose>
				<geometry>
					<cylinder>
						<radius>0.05</radius>
						<length>1.6</length>
					</cylinder>
				</geometry>
			</visual>

			<visual name='vis_horizontal_pole'>
				<pose>0 0 1.6 1.5708 0 0</pose>
				<geometry>
					<cylinder>
						<radius>0.025</radius>
						<length>1</length>
					</cylinder>
				</geometry>
			</visual>

			<!-- <mu>0.5</mu>
			<mu2>0.5</mu2> -->
		</link>




   		<link name="left_upper_leg">
   			<!-- <inertial>
        		<pose>0 0 0.5 0 0 0</pose>
      		</inertial> -->
   			<pose>0 0.3 1.6 0 0 0</pose>
   			<self_collide>0</self_collide>

   			<visual name='vis_left_hip'>
				<pose>0 0 0 1.5708 0 0</pose>
				<geometry>
					<cylinder>
            			<radius>0.05</radius>
            			<length>0.1</length>
					</cylinder>
				</geometry>
			</visual>

			<visual name='vis_left_thigh'>
				<pose>0 0 -0.3 0 0 0</pose>
				<geometry>
					<box>
						<size>.1 .1 .5</size>
					</box>
				</geometry>
			</visual>

			<collision name='col_left_hip'>
				<pose>0 0 0 1.5708 0 0</pose>
				<geometry>
					<cylinder>
            			<radius>0.05</radius>
            			<length>0.1</length>
          			</cylinder>
      			</geometry>
  			</collision>

			<collision name='col_left_thigh'>
				<pose>0 0 -0.3 0 0 0</pose>
				<geometry>
					<box>
						<size>.1 .1 .5</size>
					</box>
				</geometry>
			</collision>

			<!-- <mu>0.5</mu>
			<mu2>0.5</mu2> -->
		</link>

   		<link name="left_lower_leg">
   			<pose> 0 0.3 1 0 0 0</pose>
   			<self_collide>0</self_collide>
   			<!-- <inertial>
        		<pose>0 0 0.5 0 0 0</pose>
      		</inertial> -->
      		<visual name='vis_left_knee'>
				<pose>0 0 0 1.5708 0 0</pose>
				<geometry>
					<cylinder>
            			<radius>0.05</radius>
            			<length>0.1</length>
          			</cylinder>
				</geometry>
			</visual>

			<visual name='vis_left_shank'>
				<pose>0 0 -0.275 0 0 0</pose>
				<geometry>
					<box>
						<size>.1 .1 .45</size>
					</box>
				</geometry>
			</visual>

			<collision name='col_left_knee'>
				<pose>0 0 0 1.5708 0 0</pose>
				<geometry>
					<cylinder>
            			<radius>0.05</radius>
            			<length>0.1</length>
          			</cylinder>
				</geometry>
			</collision>

			<collision name='col_left_shank'>
				<pose>0 0 -0.275 0 0 0</pose>
				<geometry>
					<box>
						<size>.1 .1 .45</size>
					</box>
				</geometry>
			</collision>

<!-- 			<mu>0.5</mu>
			<mu2>0.5</mu2> -->
		</link>

		<link name="left_foot">
			<self_collide>0</self_collide>
			<!-- <inertial>
        		<pose>0 0 0.5 0 0 0</pose>
      		</inertial> -->
      		<pose>0 0.3 0.45 0 0 0</pose>
      		<visual name='vis_left_ankle'>
				<pose>0 0 0 1.5708 0 0</pose>
				<geometry>
					<cylinder>
						<radius>0.05</radius>
						<length>0.1</length>
					</cylinder>
				</geometry>
			</visual>

			<visual name='vis_left_sole'>
				<pose>0.05 0 -0.06 0 0 0</pose>
				<geometry>
					<box>
						<size>.3 .2 .02</size>
					</box>
				</geometry>
			</visual>

			<collision name='col_left_ankle'>
				<pose>0 0 0 1.5708 0 0</pose>
				<geometry>
					<cylinder>
						<radius>0.05</radius>
						<length>0.1</length>
					</cylinder>
				</geometry>
			</collision>

			<collision name='col_left_sole'>
				<pose>0.05 0 -0.06 0 0 0</pose>
				<geometry>
					<box>
						<size>.3 .2 .02</size>
					</box>
				</geometry>
			</collision>

		<!-- 	<mu>0.5</mu>
			<mu2>0.5</mu2> -->
		</link>

		<link name="right_upper_leg">
   			<!-- <inertial>
        		<pose>0 0 0.5 0 0 0</pose>
      		</inertial> -->
   			<pose>0 -0.3 1.6 0 0 0</pose>
   			<self_collide>0</self_collide>

   			<visual name='vis_right_hip'>
				<pose>0 0 0 1.5708 0 0</pose>
				<geometry>
					<cylinder>
            			<radius>0.05</radius>
            			<length>0.1</length>
					</cylinder>
				</geometry>
			</visual>

			<visual name='vis_right_thigh'>
				<pose>0 0 -0.3 0 0 0</pose>
				<geometry>
					<box>
						<size>.1 .1 .5</size>
					</box>
				</geometry>
			</visual>

			<collision name='col_right_hip'>
				<pose>0 0 0 1.5708 0 0</pose>
				<geometry>
					<cylinder>
            			<radius>0.05</radius>
            			<length>0.1</length>
          			</cylinder>
      			</geometry>
  			</collision>

			<collision name='col_right_thigh'>
				<pose>0 0 -0.3 0 0 0</pose>
				<geometry>
					<box>
						<size>.1 .1 .5</size>
					</box>
				</geometry>
			</collision>

			<!-- <mu>0.5</mu>
			<mu2>0.5</mu2> -->
		</link>

   		<link name="right_lower_leg">
   			<pose> 0 -0.3 1 0 0 0</pose>
   			<self_collide>0</self_collide>
   			<!-- <inertial>
        		<pose>0 0 0.5 0 0 0</pose>
      		</inertial> -->
      		<visual name='vis_right_knee'>
				<pose>0 0 0 1.5708 0 0</pose>
				<geometry>
					<cylinder>
            			<radius>0.05</radius>
            			<length>0.1</length>
          			</cylinder>
				</geometry>
			</visual>

			<visual name='vis_right_shank'>
				<pose>0 0 -0.275 0 0 0</pose>
				<geometry>
					<box>
						<size>.1 .1 .45</size>
					</box>
				</geometry>
			</visual>

			<collision name='col_right_knee'>
				<pose>0 0 0 1.5708 0 0</pose>
				<geometry>
					<cylinder>
            			<radius>0.05</radius>
            			<length>0.1</length>
          			</cylinder>
				</geometry>
			</collision>

			<collision name='col_right_shank'>
				<pose>0 0 -0.275 0 0 0</pose>
				<geometry>
					<box>
						<size>.1 .1 .45</size>
					</box>
				</geometry>
			</collision>

<!-- 			<mu>0.5</mu>
			<mu2>0.5</mu2> -->
		</link>

		<link name="right_foot">
			<self_collide>0</self_collide>
			<!-- <inertial>
        		<pose>0 0 0.5 0 0 0</pose>
      		</inertial> -->
      		<pose>0 -0.3 0.45 0 0 0</pose>
      		<visual name='vis_right_ankle'>
				<pose>0 0 0 1.5708 0 0</pose>
				<geometry>
					<cylinder>
						<radius>0.05</radius>
						<length>0.1</length>
					</cylinder>
				</geometry>
			</visual>

			<visual name='vis_right_sole'>
				<pose>0.05 0 -0.06 0 0 0</pose>
				<geometry>
					<box>
						<size>.3 .2 .02</size>
					</box>
				</geometry>
			</visual>

			<collision name='col_right_ankle'>
				<pose>0 0 0 1.5708 0 0</pose>
				<geometry>
					<cylinder>
						<radius>0.05</radius>
						<length>0.1</length>
					</cylinder>
				</geometry>
			</collision>

			<collision name='col_right_sole'>
				<pose>0.05 0 -0.06 0 0 0</pose>
				<geometry>
					<box>
						<size>.3 .2 .02</size>
					</box>
				</geometry>
			</collision>

		<!-- 	<mu>0.5</mu>
			<mu2>0.5</mu2> -->
		</link>


		<joint name="left_hip_joint" type="revolute">
			<parent>base</parent>
			<child>left_upper_leg</child>
			<axis>
				<dynamics>
          			<damping>0.01</damping>
          			<friction>0.5</friction>
        		</dynamics>
				<limit>
      				<lower>-1.74</lower>
      				<upper>0.52</upper>
      			</limit>
				<xyz>0 1 0</xyz>
			</axis>
		</joint>

		<joint name="left_knee_joint" type="revolute">
      		<parent>left_upper_leg</parent>
      		<child>left_lower_leg</child>
      		<axis>
      			<dynamics>
          			<damping>0.01</damping>
          			<friction>0.5</friction>
        		</dynamics>
      			<limit>
      				<lower>0</lower>
      				<upper>2.1</upper>
      			</limit>
        		<xyz>0 1 0</xyz>
      		</axis>
		</joint>

		<joint name="left_ankle_joint" type="revolute">
			<parent>left_lower_leg</parent>
			<child>left_foot</child>
			<axis>
				<dynamics>
          			<damping>0.01</damping>
          			<friction>0.5</friction>
        		</dynamics>
				<xyz>0 1 0</xyz>
				<limit>
					<lower>-0.52</lower>
	                <upper>0.52</upper>
	            </limit>
			</axis>
		</joint>

   		<include>
      		<uri>model://hokuyo</uri>
      		<pose>0 0.39 0.45 -1.5708 -1.5708 0</pose>
		</include>
    	<joint name="hokuyo_joint" type="fixed">

      		<child>hokuyo::link</child>
      		<parent>left_foot</parent>
    	</joint>

    	<joint name="right_hip_joint" type="revolute">
			<parent>base</parent>
			<child>right_upper_leg</child>
			<axis>
				<dynamics>
          			<damping>0.01</damping>
          			<friction>0.5</friction>
        		</dynamics>
				<limit>
      				<lower>-1.74</lower>
      				<upper>0.52</upper>
      			</limit>
				<xyz>0 1 0</xyz>
			</axis>
		</joint>

		<joint name="right_knee_joint" type="revolute">
      		<parent>right_upper_leg</parent>
      		<child>right_lower_leg</child>
      		<axis>
      			<dynamics>
          			<damping>0.01</damping>
          			<friction>0.5</friction>
        		</dynamics>
      			<limit>
      				<lower>0</lower>
      				<upper>2.1</upper>
      			</limit>
        		<xyz>0 1 0</xyz>
      		</axis>
		</joint>

		<joint name="right_ankle_joint" type="revolute">
			<parent>right_lower_leg</parent>
			<child>right_foot</child>
			<axis>
				<dynamics>
          			<damping>0.01</damping>
          			<friction>0.5</friction>
        		</dynamics>
				<xyz>0 1 0</xyz>
				<limit>
					<lower>-0.52</lower>
	                <upper>0.52</upper>
	            </limit>
			</axis>
		</joint>

<!--    		<include>
      		<uri>model://hokuyo</uri>
      			<pose>0 -0.39 0.45 1.5708 1.5708 0</pose>
		</include>
    	<joint name="hokuyo_joint" type="fixed">
      		<child>hokuyo::link</child>
      		<parent>right_foot</parent>
    	</joint> -->

</model>
</sdf>